Workbook
Name NomiGiocatori: Listone!$A$2:$A$532
Name Squadre: Impostazioni!$B$4:$B$11
Name ElencoFlag: Impostazioni!$D$23:$D$29

Sheet Istruzioni
A1: FANTATOOL — ASTA MANTRA 2026/27 (versione Excel)
A3: Questo file replica le funzioni principali dell'app Fantatool per la lega Mantra.
A5: FOGLI:
A6: • Impostazioni — budget, n. squadre, limiti e quote per ruolo, NOMI DELLE 8 SQUADRE.
A7: • Listone — tutti i 531 giocatori con quotazioni, PMA/PFC, fascia, titolarità.
A8: • Prezzi — prezzo consigliato dal motore: 'iniziale' e 'ORA' (si aggiorna con l'asta).
A9: • Motore — indici di inflazione per ruolo e globale, calcolati dagli acquisti.
A10: • Asta Live — registra qui ogni acquisto: giocatore, squadra acquirente, prezzo.
A11: • Tabellone — rose delle 8 squadre, budget speso/residuo, generato dagli acquisti.
A13: CELLE DA COMPILARE = testo BLU su sfondo GIALLO:
A14: • Impostazioni!B2:B10 (budget, n. squadre, nomi squadre)
A15: • Asta Live: colonne Giocatore, Proprietario, Prezzo (menù a tendina dove disponibile).
... A24: Ricalcolo: apri in Excel e premi F9 (o Cmd+=). Le tendine funzionano solo in Excel/LibreOffice.

Sheet Impostazioni
A1: IMPOSTAZIONI ASTA
A2: Budget per squadra | B2: 500
A3: Numero squadre | B3: 8
A4: Squadra 1 | B4: Squadra 1
A5: Squadra 2 | B5: Squadra 2
A6: Squadra 3 | B6: Squadra 3
A7: Squadra 4 | B7: Squadra 4
A8: Squadra 5 | B8: Squadra 5
A9: Squadra 6 | B9: Squadra 6
A10: Squadra 7 | B10: Squadra 7
A11: Squadra 8 | B11: Squadra 8
A13: Limiti e quote per ruolo
A14: Ruolo | B14: Slot | C14: Quota % budget
A15: P | B15: 3 | C15: 6
A16: D | B16: 11 | C16: 16
A17: C | B17: 8 | C17: 30
A18: A | B18: 8 | C18: 48
A19: TOT | B19: =SUM(B15:B18)
A21: Moltiplicatore difesa (rif.) | D21: Moltiplicatori flag
A22: Club | B22: Mult | D22: Flag | E22: Mult
A23: Como | B23: 1.19 | D23: Normale | E23: 1
A24: Inter | B24: 1.18 | D24: 🟡 Ballottaggio | E24: 0.75
A25: Roma | B25: 1.16 | D25: 🔴 Infortunato/Dubbio | E25: 0.5
A26: Juventus | B26: 1.12 | D26: 🎯 Rigorista designato | E26: 1.15
A27: Napoli | B27: 1.11 | D27: 🎯🟡 Rigorista in Ballottaggio | E27: 0.9
A28: Milan | B28: 1.09 | D28: 📈 Nuovo titolare confermato | E28: 1.2
A29: Bologna | B29: 1.08 | D29: 🪑 Riserva Fissa (da fasciaFc) | E29: 0.6
A30: Atalanta | B30: 1.05
A31: Venezia | B31: 0.85
A32: Frosinone | B32: 0.85
A33: Monza | B33: 0.85

Sheet Listone
A1: Giocatore | B1: Squadra | C1: Ruolo | D1: Ruolo Mantra | E1: Quotazione | F1: FVM | G1: PMA | H1: PFC | I1: Slot | J1: Fascia | K1: Titolarità % | L1: Fantamedia att. | M1: Rigori % | N1: Status | O1: Prezzo atteso | P1: Flag suggerito
A2: Svilar | B2: Roma | C2: P | D2: Por | E2: 19 | F2: 85 | G2: 46.05 | H2: 36.6 | I2: 1 | J2: Top | K2: 91 | L2: 5.51 | M2: 0 | N2: T | O2: 47 | P2: Normale
A3: Carnesecchi | B3: Atalanta | C3: P | D3: Por | E3: 17 | F3: 55 | G3: 31.85 | H3: 32.55 | I3: 1 | J3: Top | K3: 91 | L3: 5.46 | M3: 0 | N3: T | O3: 34 | P3: Normale
A4: Martinez Jo. | B4: Inter | C4: P | D4: Por | E4: 17 | F4: 68 | G4: 37.95 | H4: 33.95 | I4: 1 | J4: Top | K4: 86 | L4: 5.53 | M4: 0 | N4: T | O4: 41 | P4: Normale
A5: Vicario | B5: Juventus | C5: P | D5: Por | E5: 17 | F5: 70 | G5: 39.25 | H5: 32.95 | I5: 1 | J5: Top | K5: 91 | L5: 5.47 | M5: 0 | N5: T | O5: 40 | P5: Normale
A6: Butez | B6: Como | C6: P | D6: Por | E6: 15 | F6: 50 | G6: 25.65 | H6: 24.8 | I6: 1 | J6: Semi-Top | K6: 86 | L6: 5.43 | M6: 0 | N6: B | O6: 27 | P6: 🟡 Ballottaggio
A7: Maignan | B7: Milan | C7: P | D7: Por | E7: 15 | F7: 52 | G7: 34.45 | H7: 34.75 | I7: 1 | J7: Top | K7: 91 | L7: 5.5 | M7: 0 | N7: T | O7: 35 | P7: Normale
A8: De Gea | B8: Fiorentina | C8: P | D8: Por | E8: 11 | F8: 30 | G8: 7.3 | H8: 13.55 | I8: 1 | J8: Semi-Top | K8: 91 | L8: 5.19 | M8: 0 | N8: T | O8: 6 | P8: Normale
A9: Meret | B9: Napoli | C9: P | D9: Por | E9: 11 | F9: 48 | G9: 28.55 | H9: 31.2 | I9: 1 | J9: Semi-Top | K9: 86 | L9: 5.49 | M9: 0 | N9: T | O9: 29.5 | P9: Normale
A10: Caprile | B10: Cagliari | C10: P | D10: Por | E10: 10 | F10: 25 | G10: 3.25 | H10: 0.5 | I10: 2 | J10: OttimoTit | K10: 91 | L10: 5.05 | M10: 0 | N10: T | O10: 2.5 | P10: Normale
A11: Mandas | B11: Lazio | C11: P | D11: Por | E11: 10 | F11: 36 | G11: 10.5 | H11: 12.25 | I11: 2 | J11: Semi-Top | K11: 80 | L11: 5.31 | M11: 0 | N11: T | O11: 10 | P11: Normale
A12: Skorupski | B12: Bologna | C12: P | D12: Por | E12: 10 | F12: 32 | G12: 3.9 | H12: 9 | I12: 2 | J12: OttimoTit | K12: 91 | L12: 5.13 | M12: 0 | N12: T | O12: 3 | P12: Normale
A13: Okoye | B13: Udinese | C13: P | D13: Por | E13: 9 | F13: 28 | G13: 5.65 | H13: 7.3 | I13: 2 | J13: OttimoTit | K13: 91 | L13: 5.11 | M13: 0 | N13: T | O13: 5 | P13: Normale
... A445: Przyborek | B445: Lazio | C445: C | D445: W;T | E445: 1 | F445: 5 | G445: 0.7 | H445: 0.5 | I445: 8 | J445: Riserva | K445: 54 | L445: 6.07 | M445: 0 | N445: P | O445: 1 | P445: 🪑 Riserva Fissa (da fasciaFc)
A446: Sierro | B446: Parma | C446: C | D446: M;C | E446: 1 | F446: 1 | O446: 0 | P446: Normale
A447: Malen | B447: Roma | C447: A | D447: Pc | E447: 38 | F447: 450 | G447: 210.65 | H447: 219.2 | I447: 1 | J447: Top | K447: 92 | L447: 7.57 | M447: 20 | N447: T | O447: 210 | P447: Normale
A448: Martinez L. | B448: Inter | C448: A | D448: Pc | E448: 33 | F448: 361 | G448: 176.1 | H448: 204.5 | I448: 1 | J448: Top | K448: 92 | L448: 7.53 | M448: 10 | N448: T | O448: 175 | P448: Normale
A449: Hojlund | B449: Napoli | C449: A | D449: Pc | E449: 28 | F449: 260 | G449: 125.3 | H449: 152.5 | I449: 1 | J449: Top | K449: 92 | L449: 7.25 | M449: 20 | N449: T | O449: 125 | P449: Normale
A450: Thuram | B450: Inter | C450: A | D450: Pc | E450: 28 | F450: 249 | G450: 96.7 | H450: 141.85 | I450: 1 | J450: Semi-Top | K450: 90 | L450: 7.27 | M450: 0 | N450: T | O450: 100 | P450: Normale
A451: Ramos G. | B451: Milan | C451: A | D451: Pc | E451: 27 | F451: 237 | G451: 141.5 | H451: 162.9 | I451: 1 | J451: Top | K451: 92 | L451: 7.29 | M451: 70 | N451: T | O451: 144.5 | P451: 🎯 Rigorista designato
A452: Kolo Muani | B452: Juventus | C452: A | D452: Pc | E452: 25 | F452: 165 | G452: 82.65 | H452: 126.7 | I452: 1 | J452: Semi-Top | K452: 90 | L452: 7.21 | M452: 70 | N452: B | O452: 75 | P452: 🎯🟡 Rigorista in Ballottaggio
A453: Kean | B453: Como | C453: A | D453: Pc | E453: 24 | F453: 183 | G453: 75 | H453: 102.5 | I453: 1 | J453: Semi-Top | K453: 84 | L453: 7.22 | M453: 20 | N453: B | O453: 70 | P453: 🟡 Ballottaggio
A454: Woltemade | B454: Juventus | C454: A | D454: A | E454: 23 | F454: 160 | G454: 53.45 | H454: 59.8 | I454: 2 | J454: Semi-Top | K454: 86 | L454: 6.97 | M454: 20 | N454: B | O454: 52 | P454: 🟡 Ballottaggio
A455: Douvikas | B455: Como | C455: A | D455: Pc | E455: 22 | F455: 185 | G455: 53.2 | H455: 74.75 | I455: 2 | J455: Semi-Top | K455: 88 | L455: 7.01 | M455: 10 | N455: B | O455: 56 | P455: 🟡 Ballottaggio
A456: Yildiz | B456: Juventus | C456: A | D456: A | E456: 22 | F456: 100 | G456: 29.75 | H456: 38.25 | I456: 3 | J456: Riserva | K456: 69 | L456: 7.16 | M456: 0 | N456: T | O456: 30 | P456: 🔴 Infortunato/Dubbio
A457: Berardi | B457: Sassuolo | C457: A | D457: A | E457: 19 | F457: 106 | G457: 34.65 | H457: 50.8 | I457: 2 | J457: OttimoTit | K457: 88 | L457: 6.91 | M457: 70 | N457: T | O457: 32 | P457: 🔴 Infortunato/Dubbio
A458: Davis K. | B458: Udinese | C458: A | D458: Pc | E458: 19 | F458: 108 | G458: 33.35 | H458: 72.55 | I458: 2 | J458: Semi-Top | K458: 92 | L458: 6.94 | M458: 70 | N458: T | O458: 33.5 | P458: 🎯 Rigorista designato
... A532: Trepy | B532: Cagliari | C532: A | D532: Pc | E532: 1 | F532: 2 | G532: 0.9 | H532: 0.5 | I532: 6 | J532: Riserva | K532: 46 | L532: 6.3 | M532: 0 | N532: P | O532: 1 | P532: 🔴 Infortunato/Dubbio

Sheet Motore
A1: MOTORE — INDICI DI INFLAZIONE
A3: Ruolo | B3: Acquisti | C3: Spesa | D3: Ritmo reale | E3: Ritmo teorico | F3: Mult ruolo | G3: Mult globale | H3: Inflazione ruolo
A4: GLOBALE | B4: =COUNTIF('Asta Live'!$G$4:$G$403,">0") | C4: =SUM('Asta Live'!$G$4:$G$403) | D4: =C4/MAX(1,B4) | E4: =(Impostazioni!$B$3*Impostazioni!$B$2)/(Impostazioni!$B$3*Impostazioni!$B$19) | G4: =IF(C4<=(Impostazioni!$B$3*Impostazioni!$B$2)*0.15,1,MEDIAN(0.75,D4/MAX(0.1,E4),1.4))
A5: P | B5: =COUNTIF('Asta Live'!$C$4:$C$403,A5) | C5: =SUMIF('Asta Live'!$C$4:$C$403,A5,'Asta Live'!$G$4:$G$403) | D5: =IF(B5<1,0,C5/B5) | E5: =((Impostazioni!$B$3*Impostazioni!$B$2)*(Impostazioni!$C$15/100))/MAX(1,Impostazioni!$B$3*Impostazioni!$B$15) | F5: =IF(B5<3,1,MEDIAN(0.7,D5/MAX(0.1,E5),1.5)) | G5: =Motore!$G$4 | H5: =G5*0.35+F5*0.65
A6: D | B6: =COUNTIF('Asta Live'!$C$4:$C$403,A6) | C6: =SUMIF('Asta Live'!$C$4:$C$403,A6,'Asta Live'!$G$4:$G$403) | D6: =IF(B6<1,0,C6/B6) | E6: =((Impostazioni!$B$3*Impostazioni!$B$2)*(Impostazioni!$C$16/100))/MAX(1,Impostazioni!$B$3*Impostazioni!$B$16) | F6: =IF(B6<3,1,MEDIAN(0.7,D6/MAX(0.1,E6),1.5)) | G6: =Motore!$G$4 | H6: =G6*0.35+F6*0.65
A7: C | B7: =COUNTIF('Asta Live'!$C$4:$C$403,A7) | C7: =SUMIF('Asta Live'!$C$4:$C$403,A7,'Asta Live'!$G$4:$G$403) | D7: =IF(B7<1,0,C7/B7) | E7: =((Impostazioni!$B$3*Impostazioni!$B$2)*(Impostazioni!$C$17/100))/MAX(1,Impostazioni!$B$3*Impostazioni!$B$17) | F7: =IF(B7<3,1,MEDIAN(0.7,D7/MAX(0.1,E7),1.5)) | G7: =Motore!$G$4 | H7: =G7*0.35+F7*0.65
A8: A | B8: =COUNTIF('Asta Live'!$C$4:$C$403,A8) | C8: =SUMIF('Asta Live'!$C$4:$C$403,A8,'Asta Live'!$G$4:$G$403) | D8: =IF(B8<1,0,C8/B8) | E8: =((Impostazioni!$B$3*Impostazioni!$B$2)*(Impostazioni!$C$18/100))/MAX(1,Impostazioni!$B$3*Impostazioni!$B$18) | F8: =IF(B8<3,1,MEDIAN(0.7,D8/MAX(0.1,E8),1.5)) | G8: =Motore!$G$4 | H8: =G8*0.35+F8*0.65

Sheet Prezzi
A1: Giocatore | B1: Squadra | C1: Ruolo | D1: Ruolo Mantra | E1: Quotazione | F1: PMA | G1: PFC | H1: Flag | I1: Prezzo iniziale | J1: Consigliato ORA | K1: Etichetta | L1: base | M1: mult difesa
A2: Svilar | B2: Roma | C2: P | D2: Por | E2: 19 | F2: 46.05 | G2: 36.6 | H2: Normale | I2: =MAX(1,TRUNC(L2*(Impostazioni!$B$2/500)*1*M2*INDEX(Impostazioni!$E$23:$E$29,MATCH(H2,Impostazioni!$D$23:$D$29,0)))) | J2: =MAX(1,TRUNC(L2*(Impostazioni!$B$2/500)*INDEX(Motore!$A$5:$H$8,MATCH(C2,Motore!$A$5:$A$8,0),8)*M2*INDEX(Impostazioni!$E$23:$E$29,MATCH(H2,Impostazioni!$D$23:$D$29,0)))) | K2: 🌟 Nuovo Arrivo TOP | L2: 38 | M2: 1.16
A3: Carnesecchi | B3: Atalanta | C3: P | D3: Por | E3: 17 | F3: 31.85 | G3: 32.55 | H3: Normale | I3: =MAX(1,TRUNC(L3*(Impostazioni!$B$2/500)*1*M3*INDEX(Impostazioni!$E$23:$E$29,MATCH(H3,Impostazioni!$D$23:$D$29,0)))) | J3: =MAX(1,TRUNC(L3*(Impostazioni!$B$2/500)*INDEX(Motore!$A$5:$H$8,MATCH(C3,Motore!$A$5:$A$8,0),8)*M3*INDEX(Impostazioni!$E$23:$E$29,MATCH(H3,Impostazioni!$D$23:$D$29,0)))) | K3: 🌟 Nuovo Arrivo TOP | L3: 34 | M3: 1.05
A4: Martinez Jo. | B4: Inter | C4: P | D4: Por | E4: 17 | F4: 37.95 | G4: 33.95 | H4: Normale | I4: =MAX(1,TRUNC(L4*(Impostazioni!$B$2/500)*1*M4*INDEX(Impostazioni!$E$23:$E$29,MATCH(H4,Impostazioni!$D$23:$D$29,0)))) | J4: =MAX(1,TRUNC(L4*(Impostazioni!$B$2/500)*INDEX(Motore!$A$5:$H$8,MATCH(C4,Motore!$A$5:$A$8,0),8)*M4*INDEX(Impostazioni!$E$23:$E$29,MATCH(H4,Impostazioni!$D$23:$D$29,0)))) | K4: 🌟 Nuovo Arrivo TOP | L4: 34 | M4: 1.18
A5: Vicario | B5: Juventus | C5: P | D5: Por | E5: 17 | F5: 39.25 | G5: 32.95 | H5: Normale | I5: =MAX(1,TRUNC(L5*(Impostazioni!$B$2/500)*1*M5*INDEX(Impostazioni!$E$23:$E$29,MATCH(H5,Impostazioni!$D$23:$D$29,0)))) | J5: =MAX(1,TRUNC(L5*(Impostazioni!$B$2/500)*INDEX(Motore!$A$5:$H$8,MATCH(C5,Motore!$A$5:$A$8,0),8)*M5*INDEX(Impostazioni!$E$23:$E$29,MATCH(H5,Impostazioni!$D$23:$D$29,0)))) | K5: 🌟 Nuovo Arrivo TOP | L5: 34 | M5: 1.12
A6: Butez | B6: Como | C6: P | D6: Por | E6: 15 | F6: 25.65 | G6: 24.8 | H6: 🟡 Ballottaggio | I6: =MAX(1,TRUNC(L6*(Impostazioni!$B$2/500)*1*M6*INDEX(Impostazioni!$E$23:$E$29,MATCH(H6,Impostazioni!$D$23:$D$29,0)))) | J6: =MAX(1,TRUNC(L6*(Impostazioni!$B$2/500)*INDEX(Motore!$A$5:$H$8,MATCH(C6,Motore!$A$5:$A$8,0),8)*M6*INDEX(Impostazioni!$E$23:$E$29,MATCH(H6,Impostazioni!$D$23:$D$29,0)))) | K6: 🌟 Nuovo Arrivo TOP | L6: 30 | M6: 1.19
A7: Maignan | B7: Milan | C7: P | D7: Por | E7: 15 | F7: 34.45 | G7: 34.75 | H7: Normale | I7: =MAX(1,TRUNC(L7*(Impostazioni!$B$2/500)*1*M7*INDEX(Impostazioni!$E$23:$E$29,MATCH(H7,Impostazioni!$D$23:$D$29,0)))) | J7: =MAX(1,TRUNC(L7*(Impostazioni!$B$2/500)*INDEX(Motore!$A$5:$H$8,MATCH(C7,Motore!$A$5:$A$8,0),8)*M7*INDEX(Impostazioni!$E$23:$E$29,MATCH(H7,Impostazioni!$D$23:$D$29,0)))) | K7: 🌟 Nuovo Arrivo TOP | L7: 30 | M7: 1.09
A8: De Gea | B8: Fiorentina | C8: P | D8: Por | E8: 11 | F8: 7.3 | G8: 13.55 | H8: Normale | I8: =MAX(1,TRUNC(L8*(Impostazioni!$B$2/500)*1*M8*INDEX(Impostazioni!$E$23:$E$29,MATCH(H8,Impostazioni!$D$23:$D$29,0)))) | J8: =MAX(1,TRUNC(L8*(Impostazioni!$B$2/500)*INDEX(Motore!$A$5:$H$8,MATCH(C8,Motore!$A$5:$A$8,0),8)*M8*INDEX(Impostazioni!$E$23:$E$29,MATCH(H8,Impostazioni!$D$23:$D$29,0)))) | K8: Nuovo Arrivo (Rotazione) | L8: 12.1 | M8: 1
A9: Meret | B9: Napoli | C9: P | D9: Por | E9: 11 | F9: 28.55 | G9: 31.2 | H9: Normale | I9: =MAX(1,TRUNC(L9*(Impostazioni!$B$2/500)*1*M9*INDEX(Impostazioni!$E$23:$E$29,MATCH(H9,Impostazioni!$D$23:$D$29,0)))) | J9: =MAX(1,TRUNC(L9*(Impostazioni!$B$2/500)*INDEX(Motore!$A$5:$H$8,MATCH(C9,Motore!$A$5:$A$8,0),8)*M9*INDEX(Impostazioni!$E$23:$E$29,MATCH(H9,Impostazioni!$D$23:$D$29,0)))) | K9: Nuovo Arrivo (Rotazione) | L9: 12.1 | M9: 1.11
A10: Caprile | B10: Cagliari | C10: P | D10: Por | E10: 10 | F10: 3.25 | G10: 0.5 | H10: Normale | I10: =MAX(1,TRUNC(L10*(Impostazioni!$B$2/500)*1*M10*INDEX(Impostazioni!$E$23:$E$29,MATCH(H10,Impostazioni!$D$23:$D$29,0)))) | J10: =MAX(1,TRUNC(L10*(Impostazioni!$B$2/500)*INDEX(Motore!$A$5:$H$8,MATCH(C10,Motore!$A$5:$A$8,0),8)*M10*INDEX(Impostazioni!$E$23:$E$29,MATCH(H10,Impostazioni!$D$23:$D$29,0)))) | K10: Nuovo Arrivo (Rotazione) | L10: 11 | M10: 1
A11: Mandas | B11: Lazio | C11: P | D11: Por | E11: 10 | F11: 10.5 | G11: 12.25 | H11: Normale | I11: =MAX(1,TRUNC(L11*(Impostazioni!$B$2/500)*1*M11*INDEX(Impostazioni!$E$23:$E$29,MATCH(H11,Impostazioni!$D$23:$D$29,0)))) | J11: =MAX(1,TRUNC(L11*(Impostazioni!$B$2/500)*INDEX(Motore!$A$5:$H$8,MATCH(C11,Motore!$A$5:$A$8,0),8)*M11*INDEX(Impostazioni!$E$23:$E$29,MATCH(H11,Impostazioni!$D$23:$D$29,0)))) | K11: Nuovo Arrivo (Rotazione) | L11: 11 | M11: 1
A12: Skorupski | B12: Bologna | C12: P | D12: Por | E12: 10 | F12: 3.9 | G12: 9 | H12: Normale | I12: =MAX(1,TRUNC(L12*(Impostazioni!$B$2/500)*1*M12*INDEX(Impostazioni!$E$23:$E$29,MATCH(H12,Impostazioni!$D$23:$D$29,0)))) | J12: =MAX(1,TRUNC(L12*(Impostazioni!$B$2/500)*INDEX(Motore!$A$5:$H$8,MATCH(C12,Motore!$A$5:$A$8,0),8)*M12*INDEX(Impostazioni!$E$23:$E$29,MATCH(H12,Impostazioni!$D$23:$D$29,0)))) | K12: Nuovo Arrivo (Rotazione) | L12: 11 | M12: 1.08
A13: Okoye | B13: Udinese | C13: P | D13: Por | E13: 9 | F13: 5.65 | G13: 7.3 | H13: Normale | I13: =MAX(1,TRUNC(L13*(Impostazioni!$B$2/500)*1*M13*INDEX(Impostazioni!$E$23:$E$29,MATCH(H13,Impostazioni!$D$23:$D$29,0)))) | J13: =MAX(1,TRUNC(L13*(Impostazioni!$B$2/500)*INDEX(Motore!$A$5:$H$8,MATCH(C13,Motore!$A$5:$A$8,0),8)*M13*INDEX(Impostazioni!$E$23:$E$29,MATCH(H13,Impostazioni!$D$23:$D$29,0)))) | K13: Nuovo Arrivo (Rotazione) | L13: 9.9 | M13: 1
... A445: Przyborek | B445: Lazio | C445: C | D445: W;T | E445: 1 | F445: 0.7 | G445: 0.5 | H445: 🪑 Riserva Fissa (da fasciaFc) | I445: =MAX(1,TRUNC(L445*(Impostazioni!$B$2/500)*1*M445*INDEX(Impostazioni!$E$23:$E$29,MATCH(H445,Impostazioni!$D$23:$D$29,0)))) | J445: =MAX(1,TRUNC(L445*(Impostazioni!$B$2/500)*INDEX(Motore!$A$5:$H$8,MATCH(C445,Motore!$A$5:$A$8,0),8)*M445*INDEX(Impostazioni!$E$23:$E$29,MATCH(H445,Impostazioni!$D$23:$D$29,0)))) | K445: Scommessa / Sconosciuto | L445: 1 | M445: 1
A446: Sierro | B446: Parma | C446: C | D446: M;C | E446: 1 | H446: Normale | I446: =MAX(1,TRUNC(L446*(Impostazioni!$B$2/500)*1*M446*INDEX(Impostazioni!$E$23:$E$29,MATCH(H446,Impostazioni!$D$23:$D$29,0)))) | J446: =MAX(1,TRUNC(L446*(Impostazioni!$B$2/500)*INDEX(Motore!$A$5:$H$8,MATCH(C446,Motore!$A$5:$A$8,0),8)*M446*INDEX(Impostazioni!$E$23:$E$29,MATCH(H446,Impostazioni!$D$23:$D$29,0)))) | K446: Scommessa / Sconosciuto | L446: 1 | M446: 1
A447: Malen | B447: Roma | C447: A | D447: Pc | E447: 38 | F447: 210.65 | G447: 219.2 | H447: Normale | I447: =MAX(1,TRUNC(L447*(Impostazioni!$B$2/500)*1*M447*INDEX(Impostazioni!$E$23:$E$29,MATCH(H447,Impostazioni!$D$23:$D$29,0)))) | J447: =MAX(1,TRUNC(L447*(Impostazioni!$B$2/500)*INDEX(Motore!$A$5:$H$8,MATCH(C447,Motore!$A$5:$A$8,0),8)*M447*INDEX(Impostazioni!$E$23:$E$29,MATCH(H447,Impostazioni!$D$23:$D$29,0)))) | K447: 🌟 Nuovo Arrivo TOP | L447: 91.2 | M447: 1
A448: Martinez L. | B448: Inter | C448: A | D448: Pc | E448: 33 | F448: 176.1 | G448: 204.5 | H448: Normale | I448: =MAX(1,TRUNC(L448*(Impostazioni!$B$2/500)*1*M448*INDEX(Impostazioni!$E$23:$E$29,MATCH(H448,Impostazioni!$D$23:$D$29,0)))) | J448: =MAX(1,TRUNC(L448*(Impostazioni!$B$2/500)*INDEX(Motore!$A$5:$H$8,MATCH(C448,Motore!$A$5:$A$8,0),8)*M448*INDEX(Impostazioni!$E$23:$E$29,MATCH(H448,Impostazioni!$D$23:$D$29,0)))) | K448: 🌟 Nuovo Arrivo TOP | L448: 79.2 | M448: 1
A449: Hojlund | B449: Napoli | C449: A | D449: Pc | E449: 28 | F449: 125.3 | G449: 152.5 | H449: Normale | I449: =MAX(1,TRUNC(L449*(Impostazioni!$B$2/500)*1*M449*INDEX(Impostazioni!$E$23:$E$29,MATCH(H449,Impostazioni!$D$23:$D$29,0)))) | J449: =MAX(1,TRUNC(L449*(Impostazioni!$B$2/500)*INDEX(Motore!$A$5:$H$8,MATCH(C449,Motore!$A$5:$A$8,0),8)*M449*INDEX(Impostazioni!$E$23:$E$29,MATCH(H449,Impostazioni!$D$23:$D$29,0)))) | K449: 🌟 Nuovo Arrivo TOP | L449: 67.2 | M449: 1
A450: Thuram | B450: Inter | C450: A | D450: Pc | E450: 28 | F450: 96.7 | G450: 141.85 | H450: Normale | I450: =MAX(1,TRUNC(L450*(Impostazioni!$B$2/500)*1*M450*INDEX(Impostazioni!$E$23:$E$29,MATCH(H450,Impostazioni!$D$23:$D$29,0)))) | J450: =MAX(1,TRUNC(L450*(Impostazioni!$B$2/500)*INDEX(Motore!$A$5:$H$8,MATCH(C450,Motore!$A$5:$A$8,0),8)*M450*INDEX(Impostazioni!$E$23:$E$29,MATCH(H450,Impostazioni!$D$23:$D$29,0)))) | K450: 🌟 Nuovo Arrivo TOP | L450: 67.2 | M450: 1
A451: Ramos G. | B451: Milan | C451: A | D451: Pc | E451: 27 | F451: 141.5 | G451: 162.9 | H451: 🎯 Rigorista designato | I451: =MAX(1,TRUNC(L451*(Impostazioni!$B$2/500)*1*M451*INDEX(Impostazioni!$E$23:$E$29,MATCH(H451,Impostazioni!$D$23:$D$29,0)))) | J451: =MAX(1,TRUNC(L451*(Impostazioni!$B$2/500)*INDEX(Motore!$A$5:$H$8,MATCH(C451,Motore!$A$5:$A$8,0),8)*M451*INDEX(Impostazioni!$E$23:$E$29,MATCH(H451,Impostazioni!$D$23:$D$29,0)))) | K451: 🌟 Nuovo Arrivo TOP | L451: 64.8 | M451: 1
A452: Kolo Muani | B452: Juventus | C452: A | D452: Pc | E452: 25 | F452: 82.65 | G452: 126.7 | H452: 🎯🟡 Rigorista in Ballottaggio | I452: =MAX(1,TRUNC(L452*(Impostazioni!$B$2/500)*1*M452*INDEX(Impostazioni!$E$23:$E$29,MATCH(H452,Impostazioni!$D$23:$D$29,0)))) | J452: =MAX(1,TRUNC(L452*(Impostazioni!$B$2/500)*INDEX(Motore!$A$5:$H$8,MATCH(C452,Motore!$A$5:$A$8,0),8)*M452*INDEX(Impostazioni!$E$23:$E$29,MATCH(H452,Impostazioni!$D$23:$D$29,0)))) | K452: 🌟 Nuovo Arrivo TOP | L452: 60 | M452: 1
A453: Kean | B453: Como | C453: A | D453: Pc | E453: 24 | F453: 75 | G453: 102.5 | H453: 🟡 Ballottaggio | I453: =MAX(1,TRUNC(L453*(Impostazioni!$B$2/500)*1*M453*INDEX(Impostazioni!$E$23:$E$29,MATCH(H453,Impostazioni!$D$23:$D$29,0)))) | J453: =MAX(1,TRUNC(L453*(Impostazioni!$B$2/500)*INDEX(Motore!$A$5:$H$8,MATCH(C453,Motore!$A$5:$A$8,0),8)*M453*INDEX(Impostazioni!$E$23:$E$29,MATCH(H453,Impostazioni!$D$23:$D$29,0)))) | K453: 🌟 Nuovo Arrivo TOP | L453: 57.6 | M453: 1
A454: Woltemade | B454: Juventus | C454: A | D454: A | E454: 23 | F454: 53.45 | G454: 59.8 | H454: 🟡 Ballottaggio | I454: =MAX(1,TRUNC(L454*(Impostazioni!$B$2/500)*1*M454*INDEX(Impostazioni!$E$23:$E$29,MATCH(H454,Impostazioni!$D$23:$D$29,0)))) | J454: =MAX(1,TRUNC(L454*(Impostazioni!$B$2/500)*INDEX(Motore!$A$5:$H$8,MATCH(C454,Motore!$A$5:$A$8,0),8)*M454*INDEX(Impostazioni!$E$23:$E$29,MATCH(H454,Impostazioni!$D$23:$D$29,0)))) | K454: 🌟 Nuovo Arrivo TOP | L454: 55.2 | M454: 1
A455: Douvikas | B455: Como | C455: A | D455: Pc | E455: 22 | F455: 53.2 | G455: 74.75 | H455: 🟡 Ballottaggio | I455: =MAX(1,TRUNC(L455*(Impostazioni!$B$2/500)*1*M455*INDEX(Impostazioni!$E$23:$E$29,MATCH(H455,Impostazioni!$D$23:$D$29,0)))) | J455: =MAX(1,TRUNC(L455*(Impostazioni!$B$2/500)*INDEX(Motore!$A$5:$H$8,MATCH(C455,Motore!$A$5:$A$8,0),8)*M455*INDEX(Impostazioni!$E$23:$E$29,MATCH(H455,Impostazioni!$D$23:$D$29,0)))) | K455: 🌟 Nuovo Arrivo TOP | L455: 52.8 | M455: 1
A456: Yildiz | B456: Juventus | C456: A | D456: A | E456: 22 | F456: 29.75 | G456: 38.25 | H456: 🔴 Infortunato/Dubbio | I456: =MAX(1,TRUNC(L456*(Impostazioni!$B$2/500)*1*M456*INDEX(Impostazioni!$E$23:$E$29,MATCH(H456,Impostazioni!$D$23:$D$29,0)))) | J456: =MAX(1,TRUNC(L456*(Impostazioni!$B$2/500)*INDEX(Motore!$A$5:$H$8,MATCH(C456,Motore!$A$5:$A$8,0),8)*M456*INDEX(Impostazioni!$E$23:$E$29,MATCH(H456,Impostazioni!$D$23:$D$29,0)))) | K456: 🌟 Nuovo Arrivo TOP | L456: 52.8 | M456: 1
A457: Berardi | B457: Sassuolo | C457: A | D457: A | E457: 19 | F457: 34.65 | G457: 50.8 | H457: 🔴 Infortunato/Dubbio | I457: =MAX(1,TRUNC(L457*(Impostazioni!$B$2/500)*1*M457*INDEX(Impostazioni!$E$23:$E$29,MATCH(H457,Impostazioni!$D$23:$D$29,0)))) | J457: =MAX(1,TRUNC(L457*(Impostazioni!$B$2/500)*INDEX(Motore!$A$5:$H$8,MATCH(C457,Motore!$A$5:$A$8,0),8)*M457*INDEX(Impostazioni!$E$23:$E$29,MATCH(H457,Impostazioni!$D$23:$D$29,0)))) | K457: 🌟 Nuovo Arrivo TOP | L457: 45.6 | M457: 1
A458: Davis K. | B458: Udinese | C458: A | D458: Pc | E458: 19 | F458: 33.35 | G458: 72.55 | H458: 🎯 Rigorista designato | I458: =MAX(1,TRUNC(L458*(Impostazioni!$B$2/500)*1*M458*INDEX(Impostazioni!$E$23:$E$29,MATCH(H458,Impostazioni!$D$23:$D$29,0)))) | J458: =MAX(1,TRUNC(L458*(Impostazioni!$B$2/500)*INDEX(Motore!$A$5:$H$8,MATCH(C458,Motore!$A$5:$A$8,0),8)*M458*INDEX(Impostazioni!$E$23:$E$29,MATCH(H458,Impostazioni!$D$23:$D$29,0)))) | K458: 🌟 Nuovo Arrivo TOP | L458: 45.6 | M458: 1
... A532: Trepy | B532: Cagliari | C532: A | D532: Pc | E532: 1 | F532: 0.9 | G532: 0.5 | H532: 🔴 Infortunato/Dubbio | I532: =MAX(1,TRUNC(L532*(Impostazioni!$B$2/500)*1*M532*INDEX(Impostazioni!$E$23:$E$29,MATCH(H532,Impostazioni!$D$23:$D$29,0)))) | J532: =MAX(1,TRUNC(L532*(Impostazioni!$B$2/500)*INDEX(Motore!$A$5:$H$8,MATCH(C532,Motore!$A$5:$A$8,0),8)*M532*INDEX(Impostazioni!$E$23:$E$29,MATCH(H532,Impostazioni!$D$23:$D$29,0)))) | K532: Scommessa / Sconosciuto | L532: 1 | M532: 1
A534: Colonne L,M = ausiliarie del motore. 'iniziale' = a inizio asta; 'ORA' include l'inflazione corrente.

Sheet Asta Live
A1: ASTA LIVE — registra qui ogni acquisto
A2: ESEMPIO riga 4: Svilar / Squadra 1 / 46 (cancella e inizia)
A3: Giocatore | B3: Squadra | C3: Ruolo | D3: Ruolo Mantra | E3: PMA | F3: Proprietario | G3: Prezzo | H3: chiave | I3: n | J3: chiave slot
A4: Svilar | B4: =IF($A4="","",IFERROR(INDEX(Listone!$B$2:$B$532,MATCH($A4,Listone!$A$2:$A$532,0)),"?")) | C4: =IF($A4="","",IFERROR(INDEX(Listone!$C$2:$C$532,MATCH($A4,Listone!$A$2:$A$532,0)),"")) | D4: =IF($A4="","",IFERROR(INDEX(Listone!$D$2:$D$532,MATCH($A4,Listone!$A$2:$A$532,0)),"")) | E4: =IF($A4="","",IFERROR(INDEX(Listone!$G$2:$G$532,MATCH($A4,Listone!$A$2:$A$532,0)),"")) | F4: Squadra 1 | G4: 46 | H4: =IF(OR($A4="",$F4=""),"",$F4&"|"&$C4) | I4: =IF($H4="","",COUNTIF($H$4:$H4,$H4)) | J4: =IF($H4="","",$H4&"|"&$I4)
B5: =IF($A5="","",IFERROR(INDEX(Listone!$B$2:$B$532,MATCH($A5,Listone!$A$2:$A$532,0)),"?")) | C5: =IF($A5="","",IFERROR(INDEX(Listone!$C$2:$C$532,MATCH($A5,Listone!$A$2:$A$532,0)),"")) | D5: =IF($A5="","",IFERROR(INDEX(Listone!$D$2:$D$532,MATCH($A5,Listone!$A$2:$A$532,0)),"")) | E5: =IF($A5="","",IFERROR(INDEX(Listone!$G$2:$G$532,MATCH($A5,Listone!$A$2:$A$532,0)),"")) | H5: =IF(OR($A5="",$F5=""),"",$F5&"|"&$C5) | I5: =IF($H5="","",COUNTIF($H$4:$H5,$H5)) | J5: =IF($H5="","",$H5&"|"&$I5)
B6: =IF($A6="","",IFERROR(INDEX(Listone!$B$2:$B$532,MATCH($A6,Listone!$A$2:$A$532,0)),"?")) | C6: =IF($A6="","",IFERROR(INDEX(Listone!$C$2:$C$532,MATCH($A6,Listone!$A$2:$A$532,0)),"")) | D6: =IF($A6="","",IFERROR(INDEX(Listone!$D$2:$D$532,MATCH($A6,Listone!$A$2:$A$532,0)),"")) | E6: =IF($A6="","",IFERROR(INDEX(Listone!$G$2:$G$532,MATCH($A6,Listone!$A$2:$A$532,0)),"")) | H6: =IF(OR($A6="",$F6=""),"",$F6&"|"&$C6) | I6: =IF($H6="","",COUNTIF($H$4:$H6,$H6)) | J6: =IF($H6="","",$H6&"|"&$I6)
B7: =IF($A7="","",IFERROR(INDEX(Listone!$B$2:$B$532,MATCH($A7,Listone!$A$2:$A$532,0)),"?")) | C7: =IF($A7="","",IFERROR(INDEX(Listone!$C$2:$C$532,MATCH($A7,Listone!$A$2:$A$532,0)),"")) | D7: =IF($A7="","",IFERROR(INDEX(Listone!$D$2:$D$532,MATCH($A7,Listone!$A$2:$A$532,0)),"")) | E7: =IF($A7="","",IFERROR(INDEX(Listone!$G$2:$G$532,MATCH($A7,Listone!$A$2:$A$532,0)),"")) | H7: =IF(OR($A7="",$F7=""),"",$F7&"|"&$C7) | I7: =IF($H7="","",COUNTIF($H$4:$H7,$H7)) | J7: =IF($H7="","",$H7&"|"&$I7)
B8: =IF($A8="","",IFERROR(INDEX(Listone!$B$2:$B$532,MATCH($A8,Listone!$A$2:$A$532,0)),"?")) | C8: =IF($A8="","",IFERROR(INDEX(Listone!$C$2:$C$532,MATCH($A8,Listone!$A$2:$A$532,0)),"")) | D8: =IF($A8="","",IFERROR(INDEX(Listone!$D$2:$D$532,MATCH($A8,Listone!$A$2:$A$532,0)),"")) | E8: =IF($A8="","",IFERROR(INDEX(Listone!$G$2:$G$532,MATCH($A8,Listone!$A$2:$A$532,0)),"")) | H8: =IF(OR($A8="",$F8=""),"",$F8&"|"&$C8) | I8: =IF($H8="","",COUNTIF($H$4:$H8,$H8)) | J8: =IF($H8="","",$H8&"|"&$I8)
B9: =IF($A9="","",IFERROR(INDEX(Listone!$B$2:$B$532,MATCH($A9,Listone!$A$2:$A$532,0)),"?")) | C9: =IF($A9="","",IFERROR(INDEX(Listone!$C$2:$C$532,MATCH($A9,Listone!$A$2:$A$532,0)),"")) | D9: =IF($A9="","",IFERROR(INDEX(Listone!$D$2:$D$532,MATCH($A9,Listone!$A$2:$A$532,0)),"")) | E9: =IF($A9="","",IFERROR(INDEX(Listone!$G$2:$G$532,MATCH($A9,Listone!$A$2:$A$532,0)),"")) | H9: =IF(OR($A9="",$F9=""),"",$F9&"|"&$C9) | I9: =IF($H9="","",COUNTIF($H$4:$H9,$H9)) | J9: =IF($H9="","",$H9&"|"&$I9)
B10: =IF($A10="","",IFERROR(INDEX(Listone!$B$2:$B$532,MATCH($A10,Listone!$A$2:$A$532,0)),"?")) | C10: =IF($A10="","",IFERROR(INDEX(Listone!$C$2:$C$532,MATCH($A10,Listone!$A$2:$A$532,0)),"")) | D10: =IF($A10="","",IFERROR(INDEX(Listone!$D$2:$D$532,MATCH($A10,Listone!$A$2:$A$532,0)),"")) | E10: =IF($A10="","",IFERROR(INDEX(Listone!$G$2:$G$532,MATCH($A10,Listone!$A$2:$A$532,0)),"")) | H10: =IF(OR($A10="",$F10=""),"",$F10&"|"&$C10) | I10: =IF($H10="","",COUNTIF($H$4:$H10,$H10)) | J10: =IF($H10="","",$H10&"|"&$I10)
B11: =IF($A11="","",IFERROR(INDEX(Listone!$B$2:$B$532,MATCH($A11,Listone!$A$2:$A$532,0)),"?")) | C11: =IF($A11="","",IFERROR(INDEX(Listone!$C$2:$C$532,MATCH($A11,Listone!$A$2:$A$532,0)),"")) | D11: =IF($A11="","",IFERROR(INDEX(Listone!$D$2:$D$532,MATCH($A11,Listone!$A$2:$A$532,0)),"")) | E11: =IF($A11="","",IFERROR(INDEX(Listone!$G$2:$G$532,MATCH($A11,Listone!$A$2:$A$532,0)),"")) | H11: =IF(OR($A11="",$F11=""),"",$F11&"|"&$C11) | I11: =IF($H11="","",COUNTIF($H$4:$H11,$H11)) | J11: =IF($H11="","",$H11&"|"&$I11)
B12: =IF($A12="","",IFERROR(INDEX(Listone!$B$2:$B$532,MATCH($A12,Listone!$A$2:$A$532,0)),"?")) | C12: =IF($A12="","",IFERROR(INDEX(Listone!$C$2:$C$532,MATCH($A12,Listone!$A$2:$A$532,0)),"")) | D12: =IF($A12="","",IFERROR(INDEX(Listone!$D$2:$D$532,MATCH($A12,Listone!$A$2:$A$532,0)),"")) | E12: =IF($A12="","",IFERROR(INDEX(Listone!$G$2:$G$532,MATCH($A12,Listone!$A$2:$A$532,0)),"")) | H12: =IF(OR($A12="",$F12=""),"",$F12&"|"&$C12) | I12: =IF($H12="","",COUNTIF($H$4:$H12,$H12)) | J12: =IF($H12="","",$H12&"|"&$I12)
B13: =IF($A13="","",IFERROR(INDEX(Listone!$B$2:$B$532,MATCH($A13,Listone!$A$2:$A$532,0)),"?")) | C13: =IF($A13="","",IFERROR(INDEX(Listone!$C$2:$C$532,MATCH($A13,Listone!$A$2:$A$532,0)),"")) | D13: =IF($A13="","",IFERROR(INDEX(Listone!$D$2:$D$532,MATCH($A13,Listone!$A$2:$A$532,0)),"")) | E13: =IF($A13="","",IFERROR(INDEX(Listone!$G$2:$G$532,MATCH($A13,Listone!$A$2:$A$532,0)),"")) | H13: =IF(OR($A13="",$F13=""),"",$F13&"|"&$C13) | I13: =IF($H13="","",COUNTIF($H$4:$H13,$H13)) | J13: =IF($H13="","",$H13&"|"&$I13)
B14: =IF($A14="","",IFERROR(INDEX(Listone!$B$2:$B$532,MATCH($A14,Listone!$A$2:$A$532,0)),"?")) | C14: =IF($A14="","",IFERROR(INDEX(Listone!$C$2:$C$532,MATCH($A14,Listone!$A$2:$A$532,0)),"")) | D14: =IF($A14="","",IFERROR(INDEX(Listone!$D$2:$D$532,MATCH($A14,Listone!$A$2:$A$532,0)),"")) | E14: =IF($A14="","",IFERROR(INDEX(Listone!$G$2:$G$532,MATCH($A14,Listone!$A$2:$A$532,0)),"")) | H14: =IF(OR($A14="",$F14=""),"",$F14&"|"&$C14) | I14: =IF($H14="","",COUNTIF($H$4:$H14,$H14)) | J14: =IF($H14="","",$H14&"|"&$I14)
B15: =IF($A15="","",IFERROR(INDEX(Listone!$B$2:$B$532,MATCH($A15,Listone!$A$2:$A$532,0)),"?")) | C15: =IF($A15="","",IFERROR(INDEX(Listone!$C$2:$C$532,MATCH($A15,Listone!$A$2:$A$532,0)),"")) | D15: =IF($A15="","",IFERROR(INDEX(Listone!$D$2:$D$532,MATCH($A15,Listone!$A$2:$A$532,0)),"")) | E15: =IF($A15="","",IFERROR(INDEX(Listone!$G$2:$G$532,MATCH($A15,Listone!$A$2:$A$532,0)),"")) | H15: =IF(OR($A15="",$F15=""),"",$F15&"|"&$C15) | I15: =IF($H15="","",COUNTIF($H$4:$H15,$H15)) | J15: =IF($H15="","",$H15&"|"&$I15)
B16: =IF($A16="","",IFERROR(INDEX(Listone!$B$2:$B$532,MATCH($A16,Listone!$A$2:$A$532,0)),"?")) | C16: =IF($A16="","",IFERROR(INDEX(Listone!$C$2:$C$532,MATCH($A16,Listone!$A$2:$A$532,0)),"")) | D16: =IF($A16="","",IFERROR(INDEX(Listone!$D$2:$D$532,MATCH($A16,Listone!$A$2:$A$532,0)),"")) | E16: =IF($A16="","",IFERROR(INDEX(Listone!$G$2:$G$532,MATCH($A16,Listone!$A$2:$A$532,0)),"")) | H16: =IF(OR($A16="",$F16=""),"",$F16&"|"&$C16) | I16: =IF($H16="","",COUNTIF($H$4:$H16,$H16)) | J16: =IF($H16="","",$H16&"|"&$I16)
... B403: =IF($A403="","",IFERROR(INDEX(Listone!$B$2:$B$532,MATCH($A403,Listone!$A$2:$A$532,0)),"?")) | C403: =IF($A403="","",IFERROR(INDEX(Listone!$C$2:$C$532,MATCH($A403,Listone!$A$2:$A$532,0)),"")) | D403: =IF($A403="","",IFERROR(INDEX(Listone!$D$2:$D$532,MATCH($A403,Listone!$A$2:$A$532,0)),"")) | E403: =IF($A403="","",IFERROR(INDEX(Listone!$G$2:$G$532,MATCH($A403,Listone!$A$2:$A$532,0)),"")) | H403: =IF(OR($A403="",$F403=""),"",$F403&"|"&$C403) | I403: =IF($H403="","",COUNTIF($H$4:$H403,$H403)) | J403: =IF($H403="","",$H403&"|"&$I403)
A406: RIEPILOGO SQUADRE
A407: Squadra | B407: Spesi | C407: Residui | D407: P | E407: D | F407: C | G407: A | H407: Slot | I407: Stato
A408: =Impostazioni!$B$4 | B408: =SUMIF('Asta Live'!$F$4:$F$403,$A408,'Asta Live'!$G$4:$G$403) | C408: =Impostazioni!$B$2-B408 | D408: =COUNTIFS('Asta Live'!$F$4:$F$403,$A408,'Asta Live'!$C$4:$C$403,"P") | E408: =COUNTIFS('Asta Live'!$F$4:$F$403,$A408,'Asta Live'!$C$4:$C$403,"D") | F408: =COUNTIFS('Asta Live'!$F$4:$F$403,$A408,'Asta Live'!$C$4:$C$403,"C") | G408: =COUNTIFS('Asta Live'!$F$4:$F$403,$A408,'Asta Live'!$C$4:$C$403,"A") | H408: =SUM(D408:G408) | I408: =IF(AND(C408>=0,D408<=Impostazioni!$B$15,E408<=Impostazioni!$B$16,F408<=Impostazioni!$B$17,G408<=Impostazioni!$B$18),"OK","VERIFICA")
A409: =Impostazioni!$B$5 | B409: =SUMIF('Asta Live'!$F$4:$F$403,$A409,'Asta Live'!$G$4:$G$403) | C409: =Impostazioni!$B$2-B409 | D409: =COUNTIFS('Asta Live'!$F$4:$F$403,$A409,'Asta Live'!$C$4:$C$403,"P") | E409: =COUNTIFS('Asta Live'!$F$4:$F$403,$A409,'Asta Live'!$C$4:$C$403,"D") | F409: =COUNTIFS('Asta Live'!$F$4:$F$403,$A409,'Asta Live'!$C$4:$C$403,"C") | G409: =COUNTIFS('Asta Live'!$F$4:$F$403,$A409,'Asta Live'!$C$4:$C$403,"A") | H409: =SUM(D409:G409) | I409: =IF(AND(C409>=0,D409<=Impostazioni!$B$15,E409<=Impostazioni!$B$16,F409<=Impostazioni!$B$17,G409<=Impostazioni!$B$18),"OK","VERIFICA")
A410: =Impostazioni!$B$6 | B410: =SUMIF('Asta Live'!$F$4:$F$403,$A410,'Asta Live'!$G$4:$G$403) | C410: =Impostazioni!$B$2-B410 | D410: =COUNTIFS('Asta Live'!$F$4:$F$403,$A410,'Asta Live'!$C$4:$C$403,"P") | E410: =COUNTIFS('Asta Live'!$F$4:$F$403,$A410,'Asta Live'!$C$4:$C$403,"D") | F410: =COUNTIFS('Asta Live'!$F$4:$F$403,$A410,'Asta Live'!$C$4:$C$403,"C") | G410: =COUNTIFS('Asta Live'!$F$4:$F$403,$A410,'Asta Live'!$C$4:$C$403,"A") | H410: =SUM(D410:G410) | I410: =IF(AND(C410>=0,D410<=Impostazioni!$B$15,E410<=Impostazioni!$B$16,F410<=Impostazioni!$B$17,G410<=Impostazioni!$B$18),"OK","VERIFICA")
A411: =Impostazioni!$B$7 | B411: =SUMIF('Asta Live'!$F$4:$F$403,$A411,'Asta Live'!$G$4:$G$403) | C411: =Impostazioni!$B$2-B411 | D411: =COUNTIFS('Asta Live'!$F$4:$F$403,$A411,'Asta Live'!$C$4:$C$403,"P") | E411: =COUNTIFS('Asta Live'!$F$4:$F$403,$A411,'Asta Live'!$C$4:$C$403,"D") | F411: =COUNTIFS('Asta Live'!$F$4:$F$403,$A411,'Asta Live'!$C$4:$C$403,"C") | G411: =COUNTIFS('Asta Live'!$F$4:$F$403,$A411,'Asta Live'!$C$4:$C$403,"A") | H411: =SUM(D411:G411) | I411: =IF(AND(C411>=0,D411<=Impostazioni!$B$15,E411<=Impostazioni!$B$16,F411<=Impostazioni!$B$17,G411<=Impostazioni!$B$18),"OK","VERIFICA")
A412: =Impostazioni!$B$8 | B412: =SUMIF('Asta Live'!$F$4:$F$403,$A412,'Asta Live'!$G$4:$G$403) | C412: =Impostazioni!$B$2-B412 | D412: =COUNTIFS('Asta Live'!$F$4:$F$403,$A412,'Asta Live'!$C$4:$C$403,"P") | E412: =COUNTIFS('Asta Live'!$F$4:$F$403,$A412,'Asta Live'!$C$4:$C$403,"D") | F412: =COUNTIFS('Asta Live'!$F$4:$F$403,$A412,'Asta Live'!$C$4:$C$403,"C") | G412: =COUNTIFS('Asta Live'!$F$4:$F$403,$A412,'Asta Live'!$C$4:$C$403,"A") | H412: =SUM(D412:G412) | I412: =IF(AND(C412>=0,D412<=Impostazioni!$B$15,E412<=Impostazioni!$B$16,F412<=Impostazioni!$B$17,G412<=Impostazioni!$B$18),"OK","VERIFICA")
A413: =Impostazioni!$B$9 | B413: =SUMIF('Asta Live'!$F$4:$F$403,$A413,'Asta Live'!$G$4:$G$403) | C413: =Impostazioni!$B$2-B413 | D413: =COUNTIFS('Asta Live'!$F$4:$F$403,$A413,'Asta Live'!$C$4:$C$403,"P") | E413: =COUNTIFS('Asta Live'!$F$4:$F$403,$A413,'Asta Live'!$C$4:$C$403,"D") | F413: =COUNTIFS('Asta Live'!$F$4:$F$403,$A413,'Asta Live'!$C$4:$C$403,"C") | G413: =COUNTIFS('Asta Live'!$F$4:$F$403,$A413,'Asta Live'!$C$4:$C$403,"A") | H413: =SUM(D413:G413) | I413: =IF(AND(C413>=0,D413<=Impostazioni!$B$15,E413<=Impostazioni!$B$16,F413<=Impostazioni!$B$17,G413<=Impostazioni!$B$18),"OK","VERIFICA")
A414: =Impostazioni!$B$10 | B414: =SUMIF('Asta Live'!$F$4:$F$403,$A414,'Asta Live'!$G$4:$G$403) | C414: =Impostazioni!$B$2-B414 | D414: =COUNTIFS('Asta Live'!$F$4:$F$403,$A414,'Asta Live'!$C$4:$C$403,"P") | E414: =COUNTIFS('Asta Live'!$F$4:$F$403,$A414,'Asta Live'!$C$4:$C$403,"D") | F414: =COUNTIFS('Asta Live'!$F$4:$F$403,$A414,'Asta Live'!$C$4:$C$403,"C") | G414: =COUNTIFS('Asta Live'!$F$4:$F$403,$A414,'Asta Live'!$C$4:$C$403,"A") | H414: =SUM(D414:G414) | I414: =IF(AND(C414>=0,D414<=Impostazioni!$B$15,E414<=Impostazioni!$B$16,F414<=Impostazioni!$B$17,G414<=Impostazioni!$B$18),"OK","VERIFICA")
A415: =Impostazioni!$B$11 | B415: =SUMIF('Asta Live'!$F$4:$F$403,$A415,'Asta Live'!$G$4:$G$403) | C415: =Impostazioni!$B$2-B415 | D415: =COUNTIFS('Asta Live'!$F$4:$F$403,$A415,'Asta Live'!$C$4:$C$403,"P") | E415: =COUNTIFS('Asta Live'!$F$4:$F$403,$A415,'Asta Live'!$C$4:$C$403,"D") | F415: =COUNTIFS('Asta Live'!$F$4:$F$403,$A415,'Asta Live'!$C$4:$C$403,"C") | G415: =COUNTIFS('Asta Live'!$F$4:$F$403,$A415,'Asta Live'!$C$4:$C$403,"A") | H415: =SUM(D415:G415) | I415: =IF(AND(C415>=0,D415<=Impostazioni!$B$15,E415<=Impostazioni!$B$16,F415<=Impostazioni!$B$17,G415<=Impostazioni!$B$18),"OK","VERIFICA")

Sheet Tabellone
A1: TABELLONE UFFICIALE — ASTA MANTRA
A3: =Impostazioni!$B$4 | E3: =Impostazioni!$B$5 | I3: =Impostazioni!$B$6 | M3: =Impostazioni!$B$7
A4: PORTIERI | E4: PORTIERI | I4: PORTIERI | M4: PORTIERI
A5: =IFERROR(INDEX('Asta Live'!$A$4:$A$403,MATCH(Impostazioni!$B$4&"|"&"P"&"|"&1,'Asta Live'!$J$4:$J$403,0)),"") | B5: =IFERROR(INDEX('Asta Live'!$D$4:$D$403,MATCH(Impostazioni!$B$4&"|"&"P"&"|"&1,'Asta Live'!$J$4:$J$403,0)),"") | C5: =IFERROR(INDEX('Asta Live'!$G$4:$G$403,MATCH(Impostazioni!$B$4&"|"&"P"&"|"&1,'Asta Live'!$J$4:$J$403,0)),"") | E5: =IFERROR(INDEX('Asta Live'!$A$4:$A$403,MATCH(Impostazioni!$B$5&"|"&"P"&"|"&1,'Asta Live'!$J$4:$J$403,0)),"") | F5: =IFERROR(INDEX('Asta Live'!$D$4:$D$403,MATCH(Impostazioni!$B$5&"|"&"P"&"|"&1,'Asta Live'!$J$4:$J$403,0)),"") | G5: =IFERROR(INDEX('Asta Live'!$G$4:$G$403,MATCH(Impostazioni!$B$5&"|"&"P"&"|"&1,'Asta Live'!$J$4:$J$403,0)),"") | I5: =IFERROR(INDEX('Asta Live'!$A$4:$A$403,MATCH(Impostazioni!$B$6&"|"&"P"&"|"&1,'Asta Live'!$J$4:$J$403,0)),"") | J5: =IFERROR(INDEX('Asta Live'!$D$4:$D$403,MATCH(Impostazioni!$B$6&"|"&"P"&"|"&1,'Asta Live'!$J$4:$J$403,0)),"") | K5: =IFERROR(INDEX('Asta Live'!$G$4:$G$403,MATCH(Impostazioni!$B$6&"|"&"P"&"|"&1,'Asta Live'!$J$4:$J$403,0)),"") | M5: =IFERROR(INDEX('Asta Live'!$A$4:$A$403,MATCH(Impostazioni!$B$7&"|"&"P"&"|"&1,'Asta Live'!$J$4:$J$403,0)),"") | N5: =IFERROR(INDEX('Asta Live'!$D$4:$D$403,MATCH(Impostazioni!$B$7&"|"&"P"&"|"&1,'Asta Live'!$J$4:$J$403,0)),"") | O5: =IFERROR(INDEX('Asta Live'!$G$4:$G$403,MATCH(Impostazioni!$B$7&"|"&"P"&"|"&1,'Asta Live'!$J$4:$J$403,0)),"")
A6: =IFERROR(INDEX('Asta Live'!$A$4:$A$403,MATCH(Impostazioni!$B$4&"|"&"P"&"|"&2,'Asta Live'!$J$4:$J$403,0)),"") | B6: =IFERROR(INDEX('Asta Live'!$D$4:$D$403,MATCH(Impostazioni!$B$4&"|"&"P"&"|"&2,'Asta Live'!$J$4:$J$403,0)),"") | C6: =IFERROR(INDEX('Asta Live'!$G$4:$G$403,MATCH(Impostazioni!$B$4&"|"&"P"&"|"&2,'Asta Live'!$J$4:$J$403,0)),"") | E6: =IFERROR(INDEX('Asta Live'!$A$4:$A$403,MATCH(Impostazioni!$B$5&"|"&"P"&"|"&2,'Asta Live'!$J$4:$J$403,0)),"") | F6: =IFERROR(INDEX('Asta Live'!$D$4:$D$403,MATCH(Impostazioni!$B$5&"|"&"P"&"|"&2,'Asta Live'!$J$4:$J$403,0)),"") | G6: =IFERROR(INDEX('Asta Live'!$G$4:$G$403,MATCH(Impostazioni!$B$5&"|"&"P"&"|"&2,'Asta Live'!$J$4:$J$403,0)),"") | I6: =IFERROR(INDEX('Asta Live'!$A$4:$A$403,MATCH(Impostazioni!$B$6&"|"&"P"&"|"&2,'Asta Live'!$J$4:$J$403,0)),"") | J6: =IFERROR(INDEX('Asta Live'!$D$4:$D$403,MATCH(Impostazioni!$B$6&"|"&"P"&"|"&2,'Asta Live'!$J$4:$J$403,0)),"") | K6: =IFERROR(INDEX('Asta Live'!$G$4:$G$403,MATCH(Impostazioni!$B$6&"|"&"P"&"|"&2,'Asta Live'!$J$4:$J$403,0)),"") | M6: =IFERROR(INDEX('Asta Live'!$A$4:$A$403,MATCH(Impostazioni!$B$7&"|"&"P"&"|"&2,'Asta Live'!$J$4:$J$403,0)),"") | N6: =IFERROR(INDEX('Asta Live'!$D$4:$D$403,MATCH(Impostazioni!$B$7&"|"&"P"&"|"&2,'Asta Live'!$J$4:$J$403,0)),"") | O6: =IFERROR(INDEX('Asta Live'!$G$4:$G$403,MATCH(Impostazioni!$B$7&"|"&"P"&"|"&2,'Asta Live'!$J$4:$J$403,0)),"")
A7: =IFERROR(INDEX('Asta Live'!$A$4:$A$403,MATCH(Impostazioni!$B$4&"|"&"P"&"|"&3,'Asta Live'!$J$4:$J$403,0)),"") | B7: =IFERROR(INDEX('Asta Live'!$D$4:$D$403,MATCH(Impostazioni!$B$4&"|"&"P"&"|"&3,'Asta Live'!$J$4:$J$403,0)),"") | C7: =IFERROR(INDEX('Asta Live'!$G$4:$G$403,MATCH(Impostazioni!$B$4&"|"&"P"&"|"&3,'Asta Live'!$J$4:$J$403,0)),"") | E7: =IFERROR(INDEX('Asta Live'!$A$4:$A$403,MATCH(Impostazioni!$B$5&"|"&"P"&"|"&3,'Asta Live'!$J$4:$J$403,0)),"") | F7: =IFERROR(INDEX('Asta Live'!$D$4:$D$403,MATCH(Impostazioni!$B$5&"|"&"P"&"|"&3,'Asta Live'!$J$4:$J$403,0)),"") | G7: =IFERROR(INDEX('Asta Live'!$G$4:$G$403,MATCH(Impostazioni!$B$5&"|"&"P"&"|"&3,'Asta Live'!$J$4:$J$403,0)),"") | I7: =IFERROR(INDEX('Asta Live'!$A$4:$A$403,MATCH(Impostazioni!$B$6&"|"&"P"&"|"&3,'Asta Live'!$J$4:$J$403,0)),"") | J7: =IFERROR(INDEX('Asta Live'!$D$4:$D$403,MATCH(Impostazioni!$B$6&"|"&"P"&"|"&3,'Asta Live'!$J$4:$J$403,0)),"") | K7: =IFERROR(INDEX('Asta Live'!$G$4:$G$403,MATCH(Impostazioni!$B$6&"|"&"P"&"|"&3,'Asta Live'!$J$4:$J$403,0)),"") | M7: =IFERROR(INDEX('Asta Live'!$A$4:$A$403,MATCH(Impostazioni!$B$7&"|"&"P"&"|"&3,'Asta Live'!$J$4:$J$403,0)),"") | N7: =IFERROR(INDEX('Asta Live'!$D$4:$D$403,MATCH(Impostazioni!$B$7&"|"&"P"&"|"&3,'Asta Live'!$J$4:$J$403,0)),"") | O7: =IFERROR(INDEX('Asta Live'!$G$4:$G$403,MATCH(Impostazioni!$B$7&"|"&"P"&"|"&3,'Asta Live'!$J$4:$J$403,0)),"")
A8: Totale Portieri | C8: =SUM(C5:C7) | E8: Totale Portieri | G8: =SUM(G5:G7) | I8: Totale Portieri | K8: =SUM(K5:K7) | M8: Totale Portieri | O8: =SUM(O5:O7)
A9: DIFENSORI | E9: DIFENSORI | I9: DIFENSORI | M9: DIFENSORI
A10: =IFERROR(INDEX('Asta Live'!$A$4:$A$403,MATCH(Impostazioni!$B$4&"|"&"D"&"|"&1,'Asta Live'!$J$4:$J$403,0)),"") | B10: =IFERROR(INDEX('Asta Live'!$D$4:$D$403,MATCH(Impostazioni!$B$4&"|"&"D"&"|"&1,'Asta Live'!$J$4:$J$403,0)),"") | C10: =IFERROR(INDEX('Asta Live'!$G$4:$G$403,MATCH(Impostazioni!$B$4&"|"&"D"&"|"&1,'Asta Live'!$J$4:$J$403,0)),"") | E10: =IFERROR(INDEX('Asta Live'!$A$4:$A$403,MATCH(Impostazioni!$B$5&"|"&"D"&"|"&1,'Asta Live'!$J$4:$J$403,0)),"") | F10: =IFERROR(INDEX('Asta Live'!$D$4:$D$403,MATCH(Impostazioni!$B$5&"|"&"D"&"|"&1,'Asta Live'!$J$4:$J$403,0)),"") | G10: =IFERROR(INDEX('Asta Live'!$G$4:$G$403,MATCH(Impostazioni!$B$5&"|"&"D"&"|"&1,'Asta Live'!$J$4:$J$403,0)),"") | I10: =IFERROR(INDEX('Asta Live'!$A$4:$A$403,MATCH(Impostazioni!$B$6&"|"&"D"&"|"&1,'Asta Live'!$J$4:$J$403,0)),"") | J10: =IFERROR(INDEX('Asta Live'!$D$4:$D$403,MATCH(Impostazioni!$B$6&"|"&"D"&"|"&1,'Asta Live'!$J$4:$J$403,0)),"") | K10: =IFERROR(INDEX('Asta Live'!$G$4:$G$403,MATCH(Impostazioni!$B$6&"|"&"D"&"|"&1,'Asta Live'!$J$4:$J$403,0)),"") | M10: =IFERROR(INDEX('Asta Live'!$A$4:$A$403,MATCH(Impostazioni!$B$7&"|"&"D"&"|"&1,'Asta Live'!$J$4:$J$403,0)),"") | N10: =IFERROR(INDEX('Asta Live'!$D$4:$D$403,MATCH(Impostazioni!$B$7&"|"&"D"&"|"&1,'Asta Live'!$J$4:$J$403,0)),"") | O10: =IFERROR(INDEX('Asta Live'!$G$4:$G$403,MATCH(Impostazioni!$B$7&"|"&"D"&"|"&1,'Asta Live'!$J$4:$J$403,0)),"")
A11: =IFERROR(INDEX('Asta Live'!$A$4:$A$403,MATCH(Impostazioni!$B$4&"|"&"D"&"|"&2,'Asta Live'!$J$4:$J$403,0)),"") | B11: =IFERROR(INDEX('Asta Live'!$D$4:$D$403,MATCH(Impostazioni!$B$4&"|"&"D"&"|"&2,'Asta Live'!$J$4:$J$403,0)),"") | C11: =IFERROR(INDEX('Asta Live'!$G$4:$G$403,MATCH(Impostazioni!$B$4&"|"&"D"&"|"&2,'Asta Live'!$J$4:$J$403,0)),"") | E11: =IFERROR(INDEX('Asta Live'!$A$4:$A$403,MATCH(Impostazioni!$B$5&"|"&"D"&"|"&2,'Asta Live'!$J$4:$J$403,0)),"") | F11: =IFERROR(INDEX('Asta Live'!$D$4:$D$403,MATCH(Impostazioni!$B$5&"|"&"D"&"|"&2,'Asta Live'!$J$4:$J$403,0)),"") | G11: =IFERROR(INDEX('Asta Live'!$G$4:$G$403,MATCH(Impostazioni!$B$5&"|"&"D"&"|"&2,'Asta Live'!$J$4:$J$403,0)),"") | I11: =IFERROR(INDEX('Asta Live'!$A$4:$A$403,MATCH(Impostazioni!$B$6&"|"&"D"&"|"&2,'Asta Live'!$J$4:$J$403,0)),"") | J11: =IFERROR(INDEX('Asta Live'!$D$4:$D$403,MATCH(Impostazioni!$B$6&"|"&"D"&"|"&2,'Asta Live'!$J$4:$J$403,0)),"") | K11: =IFERROR(INDEX('Asta Live'!$G$4:$G$403,MATCH(Impostazioni!$B$6&"|"&"D"&"|"&2,'Asta Live'!$J$4:$J$403,0)),"") | M11: =IFERROR(INDEX('Asta Live'!$A$4:$A$403,MATCH(Impostazioni!$B$7&"|"&"D"&"|"&2,'Asta Live'!$J$4:$J$403,0)),"") | N11: =IFERROR(INDEX('Asta Live'!$D$4:$D$403,MATCH(Impostazioni!$B$7&"|"&"D"&"|"&2,'Asta Live'!$J$4:$J$403,0)),"") | O11: =IFERROR(INDEX('Asta Live'!$G$4:$G$403,MATCH(Impostazioni!$B$7&"|"&"D"&"|"&2,'Asta Live'!$J$4:$J$403,0)),"")
A12: =IFERROR(INDEX('Asta Live'!$A$4:$A$403,MATCH(Impostazioni!$B$4&"|"&"D"&"|"&3,'Asta Live'!$J$4:$J$403,0)),"") | B12: =IFERROR(INDEX('Asta Live'!$D$4:$D$403,MATCH(Impostazioni!$B$4&"|"&"D"&"|"&3,'Asta Live'!$J$4:$J$403,0)),"") | C12: =IFERROR(INDEX('Asta Live'!$G$4:$G$403,MATCH(Impostazioni!$B$4&"|"&"D"&"|"&3,'Asta Live'!$J$4:$J$403,0)),"") | E12: =IFERROR(INDEX('Asta Live'!$A$4:$A$403,MATCH(Impostazioni!$B$5&"|"&"D"&"|"&3,'Asta Live'!$J$4:$J$403,0)),"") | F12: =IFERROR(INDEX('Asta Live'!$D$4:$D$403,MATCH(Impostazioni!$B$5&"|"&"D"&"|"&3,'Asta Live'!$J$4:$J$403,0)),"") | G12: =IFERROR(INDEX('Asta Live'!$G$4:$G$403,MATCH(Impostazioni!$B$5&"|"&"D"&"|"&3,'Asta Live'!$J$4:$J$403,0)),"") | I12: =IFERROR(INDEX('Asta Live'!$A$4:$A$403,MATCH(Impostazioni!$B$6&"|"&"D"&"|"&3,'Asta Live'!$J$4:$J$403,0)),"") | J12: =IFERROR(INDEX('Asta Live'!$D$4:$D$403,MATCH(Impostazioni!$B$6&"|"&"D"&"|"&3,'Asta Live'!$J$4:$J$403,0)),"") | K12: =IFERROR(INDEX('Asta Live'!$G$4:$G$403,MATCH(Impostazioni!$B$6&"|"&"D"&"|"&3,'Asta Live'!$J$4:$J$403,0)),"") | M12: =IFERROR(INDEX('Asta Live'!$A$4:$A$403,MATCH(Impostazioni!$B$7&"|"&"D"&"|"&3,'Asta Live'!$J$4:$J$403,0)),"") | N12: =IFERROR(INDEX('Asta Live'!$D$4:$D$403,MATCH(Impostazioni!$B$7&"|"&"D"&"|"&3,'Asta Live'!$J$4:$J$403,0)),"") | O12: =IFERROR(INDEX('Asta Live'!$G$4:$G$403,MATCH(Impostazioni!$B$7&"|"&"D"&"|"&3,'Asta Live'!$J$4:$J$403,0)),"")
A13: =IFERROR(INDEX('Asta Live'!$A$4:$A$403,MATCH(Impostazioni!$B$4&"|"&"D"&"|"&4,'Asta Live'!$J$4:$J$403,0)),"") | B13: =IFERROR(INDEX('Asta Live'!$D$4:$D$403,MATCH(Impostazioni!$B$4&"|"&"D"&"|"&4,'Asta Live'!$J$4:$J$403,0)),"") | C13: =IFERROR(INDEX('Asta Live'!$G$4:$G$403,MATCH(Impostazioni!$B$4&"|"&"D"&"|"&4,'Asta Live'!$J$4:$J$403,0)),"") | E13: =IFERROR(INDEX('Asta Live'!$A$4:$A$403,MATCH(Impostazioni!$B$5&"|"&"D"&"|"&4,'Asta Live'!$J$4:$J$403,0)),"") | F13: =IFERROR(INDEX('Asta Live'!$D$4:$D$403,MATCH(Impostazioni!$B$5&"|"&"D"&"|"&4,'Asta Live'!$J$4:$J$403,0)),"") | G13: =IFERROR(INDEX('Asta Live'!$G$4:$G$403,MATCH(Impostazioni!$B$5&"|"&"D"&"|"&4,'Asta Live'!$J$4:$J$403,0)),"") | I13: =IFERROR(INDEX('Asta Live'!$A$4:$A$403,MATCH(Impostazioni!$B$6&"|"&"D"&"|"&4,'Asta Live'!$J$4:$J$403,0)),"") | J13: =IFERROR(INDEX('Asta Live'!$D$4:$D$403,MATCH(Impostazioni!$B$6&"|"&"D"&"|"&4,'Asta Live'!$J$4:$J$403,0)),"") | K13: =IFERROR(INDEX('Asta Live'!$G$4:$G$403,MATCH(Impostazioni!$B$6&"|"&"D"&"|"&4,'Asta Live'!$J$4:$J$403,0)),"") | M13: =IFERROR(INDEX('Asta Live'!$A$4:$A$403,MATCH(Impostazioni!$B$7&"|"&"D"&"|"&4,'Asta Live'!$J$4:$J$403,0)),"") | N13: =IFERROR(INDEX('Asta Live'!$D$4:$D$403,MATCH(Impostazioni!$B$7&"|"&"D"&"|"&4,'Asta Live'!$J$4:$J$403,0)),"") | O13: =IFERROR(INDEX('Asta Live'!$G$4:$G$403,MATCH(Impostazioni!$B$7&"|"&"D"&"|"&4,'Asta Live'!$J$4:$J$403,0)),"")
A14: =IFERROR(INDEX('Asta Live'!$A$4:$A$403,MATCH(Impostazioni!$B$4&"|"&"D"&"|"&5,'Asta Live'!$J$4:$J$403,0)),"") | B14: =IFERROR(INDEX('Asta Live'!$D$4:$D$403,MATCH(Impostazioni!$B$4&"|"&"D"&"|"&5,'Asta Live'!$J$4:$J$403,0)),"") | C14: =IFERROR(INDEX('Asta Live'!$G$4:$G$403,MATCH(Impostazioni!$B$4&"|"&"D"&"|"&5,'Asta Live'!$J$4:$J$403,0)),"") | E14: =IFERROR(INDEX('Asta Live'!$A$4:$A$403,MATCH(Impostazioni!$B$5&"|"&"D"&"|"&5,'Asta Live'!$J$4:$J$403,0)),"") | F14: =IFERROR(INDEX('Asta Live'!$D$4:$D$403,MATCH(Impostazioni!$B$5&"|"&"D"&"|"&5,'Asta Live'!$J$4:$J$403,0)),"") | G14: =IFERROR(INDEX('Asta Live'!$G$4:$G$403,MATCH(Impostazioni!$B$5&"|"&"D"&"|"&5,'Asta Live'!$J$4:$J$403,0)),"") | I14: =IFERROR(INDEX('Asta Live'!$A$4:$A$403,MATCH(Impostazioni!$B$6&"|"&"D"&"|"&5,'Asta Live'!$J$4:$J$403,0)),"") | J14: =IFERROR(INDEX('Asta Live'!$D$4:$D$403,MATCH(Impostazioni!$B$6&"|"&"D"&"|"&5,'Asta Live'!$J$4:$J$403,0)),"") | K14: =IFERROR(INDEX('Asta Live'!$G$4:$G$403,MATCH(Impostazioni!$B$6&"|"&"D"&"|"&5,'Asta Live'!$J$4:$J$403,0)),"") | M14: =IFERROR(INDEX('Asta Live'!$A$4:$A$403,MATCH(Impostazioni!$B$7&"|"&"D"&"|"&5,'Asta Live'!$J$4:$J$403,0)),"") | N14: =IFERROR(INDEX('Asta Live'!$D$4:$D$403,MATCH(Impostazioni!$B$7&"|"&"D"&"|"&5,'Asta Live'!$J$4:$J$403,0)),"") | O14: =IFERROR(INDEX('Asta Live'!$G$4:$G$403,MATCH(Impostazioni!$B$7&"|"&"D"&"|"&5,'Asta Live'!$J$4:$J$403,0)),"")
A15: =IFERROR(INDEX('Asta Live'!$A$4:$A$403,MATCH(Impostazioni!$B$4&"|"&"D"&"|"&6,'Asta Live'!$J$4:$J$403,0)),"") | B15: =IFERROR(INDEX('Asta Live'!$D$4:$D$403,MATCH(Impostazioni!$B$4&"|"&"D"&"|"&6,'Asta Live'!$J$4:$J$403,0)),"") | C15: =IFERROR(INDEX('Asta Live'!$G$4:$G$403,MATCH(Impostazioni!$B$4&"|"&"D"&"|"&6,'Asta Live'!$J$4:$J$403,0)),"") | E15: =IFERROR(INDEX('Asta Live'!$A$4:$A$403,MATCH(Impostazioni!$B$5&"|"&"D"&"|"&6,'Asta Live'!$J$4:$J$403,0)),"") | F15: =IFERROR(INDEX('Asta Live'!$D$4:$D$403,MATCH(Impostazioni!$B$5&"|"&"D"&"|"&6,'Asta Live'!$J$4:$J$403,0)),"") | G15: =IFERROR(INDEX('Asta Live'!$G$4:$G$403,MATCH(Impostazioni!$B$5&"|"&"D"&"|"&6,'Asta Live'!$J$4:$J$403,0)),"") | I15: =IFERROR(INDEX('Asta Live'!$A$4:$A$403,MATCH(Impostazioni!$B$6&"|"&"D"&"|"&6,'Asta Live'!$J$4:$J$403,0)),"") | J15: =IFERROR(INDEX('Asta Live'!$D$4:$D$403,MATCH(Impostazioni!$B$6&"|"&"D"&"|"&6,'Asta Live'!$J$4:$J$403,0)),"") | K15: =IFERROR(INDEX('Asta Live'!$G$4:$G$403,MATCH(Impostazioni!$B$6&"|"&"D"&"|"&6,'Asta Live'!$J$4:$J$403,0)),"") | M15: =IFERROR(INDEX('Asta Live'!$A$4:$A$403,MATCH(Impostazioni!$B$7&"|"&"D"&"|"&6,'Asta Live'!$J$4:$J$403,0)),"") | N15: =IFERROR(INDEX('Asta Live'!$D$4:$D$403,MATCH(Impostazioni!$B$7&"|"&"D"&"|"&6,'Asta Live'!$J$4:$J$403,0)),"") | O15: =IFERROR(INDEX('Asta Live'!$G$4:$G$403,MATCH(Impostazioni!$B$7&"|"&"D"&"|"&6,'Asta Live'!$J$4:$J$403,0)),"")
A16: =IFERROR(INDEX('Asta Live'!$A$4:$A$403,MATCH(Impostazioni!$B$4&"|"&"D"&"|"&7,'Asta Live'!$J$4:$J$403,0)),"") | B16: =IFERROR(INDEX('Asta Live'!$D$4:$D$403,MATCH(Impostazioni!$B$4&"|"&"D"&"|"&7,'Asta Live'!$J$4:$J$403,0)),"") | C16: =IFERROR(INDEX('Asta Live'!$G$4:$G$403,MATCH(Impostazioni!$B$4&"|"&"D"&"|"&7,'Asta Live'!$J$4:$J$403,0)),"") | E16: =IFERROR(INDEX('Asta Live'!$A$4:$A$403,MATCH(Impostazioni!$B$5&"|"&"D"&"|"&7,'Asta Live'!$J$4:$J$403,0)),"") | F16: =IFERROR(INDEX('Asta Live'!$D$4:$D$403,MATCH(Impostazioni!$B$5&"|"&"D"&"|"&7,'Asta Live'!$J$4:$J$403,0)),"") | G16: =IFERROR(INDEX('Asta Live'!$G$4:$G$403,MATCH(Impostazioni!$B$5&"|"&"D"&"|"&7,'Asta Live'!$J$4:$J$403,0)),"") | I16: =IFERROR(INDEX('Asta Live'!$A$4:$A$403,MATCH(Impostazioni!$B$6&"|"&"D"&"|"&7,'Asta Live'!$J$4:$J$403,0)),"") | J16: =IFERROR(INDEX('Asta Live'!$D$4:$D$403,MATCH(Impostazioni!$B$6&"|"&"D"&"|"&7,'Asta Live'!$J$4:$J$403,0)),"") | K16: =IFERROR(INDEX('Asta Live'!$G$4:$G$403,MATCH(Impostazioni!$B$6&"|"&"D"&"|"&7,'Asta Live'!$J$4:$J$403,0)),"") | M16: =IFERROR(INDEX('Asta Live'!$A$4:$A$403,MATCH(Impostazioni!$B$7&"|"&"D"&"|"&7,'Asta Live'!$J$4:$J$403,0)),"") | N16: =IFERROR(INDEX('Asta Live'!$D$4:$D$403,MATCH(Impostazioni!$B$7&"|"&"D"&"|"&7,'Asta Live'!$J$4:$J$403,0)),"") | O16: =IFERROR(INDEX('Asta Live'!$G$4:$G$403,MATCH(Impostazioni!$B$7&"|"&"D"&"|"&7,'Asta Live'!$J$4:$J$403,0)),"")
A17: =IFERROR(INDEX('Asta Live'!$A$4:$A$403,MATCH(Impostazioni!$B$4&"|"&"D"&"|"&8,'Asta Live'!$J$4:$J$403,0)),"") | B17: =IFERROR(INDEX('Asta Live'!$D$4:$D$403,MATCH(Impostazioni!$B$4&"|"&"D"&"|"&8,'Asta Live'!$J$4:$J$403,0)),"") | C17: =IFERROR(INDEX('Asta Live'!$G$4:$G$403,MATCH(Impostazioni!$B$4&"|"&"D"&"|"&8,'Asta Live'!$J$4:$J$403,0)),"") | E17: =IFERROR(INDEX('Asta Live'!$A$4:$A$403,MATCH(Impostazioni!$B$5&"|"&"D"&"|"&8,'Asta Live'!$J$4:$J$403,0)),"") | F17: =IFERROR(INDEX('Asta Live'!$D$4:$D$403,MATCH(Impostazioni!$B$5&"|"&"D"&"|"&8,'Asta Live'!$J$4:$J$403,0)),"") | G17: =IFERROR(INDEX('Asta Live'!$G$4:$G$403,MATCH(Impostazioni!$B$5&"|"&"D"&"|"&8,'Asta Live'!$J$4:$J$403,0)),"") | I17: =IFERROR(INDEX('Asta Live'!$A$4:$A$403,MATCH(Impostazioni!$B$6&"|"&"D"&"|"&8,'Asta Live'!$J$4:$J$403,0)),"") | J17: =IFERROR(INDEX('Asta Live'!$D$4:$D$403,MATCH(Impostazioni!$B$6&"|"&"D"&"|"&8,'Asta Live'!$J$4:$J$403,0)),"") | K17: =IFERROR(INDEX('Asta Live'!$G$4:$G$403,MATCH(Impostazioni!$B$6&"|"&"D"&"|"&8,'Asta Live'!$J$4:$J$403,0)),"") | M17: =IFERROR(INDEX('Asta Live'!$A$4:$A$403,MATCH(Impostazioni!$B$7&"|"&"D"&"|"&8,'Asta Live'!$J$4:$J$403,0)),"") | N17: =IFERROR(INDEX('Asta Live'!$D$4:$D$403,MATCH(Impostazioni!$B$7&"|"&"D"&"|"&8,'Asta Live'!$J$4:$J$403,0)),"") | O17: =IFERROR(INDEX('Asta Live'!$G$4:$G$403,MATCH(Impostazioni!$B$7&"|"&"D"&"|"&8,'Asta Live'!$J$4:$J$403,0)),"")
A18: =IFERROR(INDEX('Asta Live'!$A$4:$A$403,MATCH(Impostazioni!$B$4&"|"&"D"&"|"&9,'Asta Live'!$J$4:$J$403,0)),"") | B18: =IFERROR(INDEX('Asta Live'!$D$4:$D$403,MATCH(Impostazioni!$B$4&"|"&"D"&"|"&9,'Asta Live'!$J$4:$J$403,0)),"") | C18: =IFERROR(INDEX('Asta Live'!$G$4:$G$403,MATCH(Impostazioni!$B$4&"|"&"D"&"|"&9,'Asta Live'!$J$4:$J$403,0)),"") | E18: =IFERROR(INDEX('Asta Live'!$A$4:$A$403,MATCH(Impostazioni!$B$5&"|"&"D"&"|"&9,'Asta Live'!$J$4:$J$403,0)),"") | F18: =IFERROR(INDEX('Asta Live'!$D$4:$D$403,MATCH(Impostazioni!$B$5&"|"&"D"&"|"&9,'Asta Live'!$J$4:$J$403,0)),"") | G18: =IFERROR(INDEX('Asta Live'!$G$4:$G$403,MATCH(Impostazioni!$B$5&"|"&"D"&"|"&9,'Asta Live'!$J$4:$J$403,0)),"") | I18: =IFERROR(INDEX('Asta Live'!$A$4:$A$403,MATCH(Impostazioni!$B$6&"|"&"D"&"|"&9,'Asta Live'!$J$4:$J$403,0)),"") | J18: =IFERROR(INDEX('Asta Live'!$D$4:$D$403,MATCH(Impostazioni!$B$6&"|"&"D"&"|"&9,'Asta Live'!$J$4:$J$403,0)),"") | K18: =IFERROR(INDEX('Asta Live'!$G$4:$G$403,MATCH(Impostazioni!$B$6&"|"&"D"&"|"&9,'Asta Live'!$J$4:$J$403,0)),"") | M18: =IFERROR(INDEX('Asta Live'!$A$4:$A$403,MATCH(Impostazioni!$B$7&"|"&"D"&"|"&9,'Asta Live'!$J$4:$J$403,0)),"") | N18: =IFERROR(INDEX('Asta Live'!$D$4:$D$403,MATCH(Impostazioni!$B$7&"|"&"D"&"|"&9,'Asta Live'!$J$4:$J$403,0)),"") | O18: =IFERROR(INDEX('Asta Live'!$G$4:$G$403,MATCH(Impostazioni!$B$7&"|"&"D"&"|"&9,'Asta Live'!$J$4:$J$403,0)),"")
A19: =IFERROR(INDEX('Asta Live'!$A$4:$A$403,MATCH(Impostazioni!$B$4&"|"&"D"&"|"&10,'Asta Live'!$J$4:$J$403,0)),"") | B19: =IFERROR(INDEX('Asta Live'!$D$4:$D$403,MATCH(Impostazioni!$B$4&"|"&"D"&"|"&10,'Asta Live'!$J$4:$J$403,0)),"") | C19: =IFERROR(INDEX('Asta Live'!$G$4:$G$403,MATCH(Impostazioni!$B$4&"|"&"D"&"|"&10,'Asta Live'!$J$4:$J$403,0)),"") | E19: =IFERROR(INDEX('Asta Live'!$A$4:$A$403,MATCH(Impostazioni!$B$5&"|"&"D"&"|"&10,'Asta Live'!$J$4:$J$403,0)),"") | F19: =IFERROR(INDEX('Asta Live'!$D$4:$D$403,MATCH(Impostazioni!$B$5&"|"&"D"&"|"&10,'Asta Live'!$J$4:$J$403,0)),"") | G19: =IFERROR(INDEX('Asta Live'!$G$4:$G$403,MATCH(Impostazioni!$B$5&"|"&"D"&"|"&10,'Asta Live'!$J$4:$J$403,0)),"") | I19: =IFERROR(INDEX('Asta Live'!$A$4:$A$403,MATCH(Impostazioni!$B$6&"|"&"D"&"|"&10,'Asta Live'!$J$4:$J$403,0)),"") | J19: =IFERROR(INDEX('Asta Live'!$D$4:$D$403,MATCH(Impostazioni!$B$6&"|"&"D"&"|"&10,'Asta Live'!$J$4:$J$403,0)),"") | K19: =IFERROR(INDEX('Asta Live'!$G$4:$G$403,MATCH(Impostazioni!$B$6&"|"&"D"&"|"&10,'Asta Live'!$J$4:$J$403,0)),"") | M19: =IFERROR(INDEX('Asta Live'!$A$4:$A$403,MATCH(Impostazioni!$B$7&"|"&"D"&"|"&10,'Asta Live'!$J$4:$J$403,0)),"") | N19: =IFERROR(INDEX('Asta Live'!$D$4:$D$403,MATCH(Impostazioni!$B$7&"|"&"D"&"|"&10,'Asta Live'!$J$4:$J$403,0)),"") | O19: =IFERROR(INDEX('Asta Live'!$G$4:$G$403,MATCH(Impostazioni!$B$7&"|"&"D"&"|"&10,'Asta Live'!$J$4:$J$403,0)),"")
A20: =IFERROR(INDEX('Asta Live'!$A$4:$A$403,MATCH(Impostazioni!$B$4&"|"&"D"&"|"&11,'Asta Live'!$J$4:$J$403,0)),"") | B20: =IFERROR(INDEX('Asta Live'!$D$4:$D$403,MATCH(Impostazioni!$B$4&"|"&"D"&"|"&11,'Asta Live'!$J$4:$J$403,0)),"") | C20: =IFERROR(INDEX('Asta Live'!$G$4:$G$403,MATCH(Impostazioni!$B$4&"|"&"D"&"|"&11,'Asta Live'!$J$4:$J$403,0)),"") | E20: =IFERROR(INDEX('Asta Live'!$A$4:$A$403,MATCH(Impostazioni!$B$5&"|"&"D"&"|"&11,'Asta Live'!$J$4:$J$403,0)),"") | F20: =IFERROR(INDEX('Asta Live'!$D$4:$D$403,MATCH(Impostazioni!$B$5&"|"&"D"&"|"&11,'Asta Live'!$J$4:$J$403,0)),"") | G20: =IFERROR(INDEX('Asta Live'!$G$4:$G$403,MATCH(Impostazioni!$B$5&"|"&"D"&"|"&11,'Asta Live'!$J$4:$J$403,0)),"") | I20: =IFERROR(INDEX('Asta Live'!$A$4:$A$403,MATCH(Impostazioni!$B$6&"|"&"D"&"|"&11,'Asta Live'!$J$4:$J$403,0)),"") | J20: =IFERROR(INDEX('Asta Live'!$D$4:$D$403,MATCH(Impostazioni!$B$6&"|"&"D"&"|"&11,'Asta Live'!$J$4:$J$403,0)),"") | K20: =IFERROR(INDEX('Asta Live'!$G$4:$G$403,MATCH(Impostazioni!$B$6&"|"&"D"&"|"&11,'Asta Live'!$J$4:$J$403,0)),"") | M20: =IFERROR(INDEX('Asta Live'!$A$4:$A$403,MATCH(Impostazioni!$B$7&"|"&"D"&"|"&11,'Asta Live'!$J$4:$J$403,0)),"") | N20: =IFERROR(INDEX('Asta Live'!$D$4:$D$403,MATCH(Impostazioni!$B$7&"|"&"D"&"|"&11,'Asta Live'!$J$4:$J$403,0)),"") | O20: =IFERROR(INDEX('Asta Live'!$G$4:$G$403,MATCH(Impostazioni!$B$7&"|"&"D"&"|"&11,'Asta Live'!$J$4:$J$403,0)),"")
A21: Totale Difensori | C21: =SUM(C10:C20) | E21: Totale Difensori | G21: =SUM(G10:G20) | I21: Totale Difensori | K21: =SUM(K10:K20) | M21: Totale Difensori | O21: =SUM(O10:O20)
A22: CENTROCAMPISTI | E22: CENTROCAMPISTI | I22: CENTROCAMPISTI | M22: CENTROCAMPISTI
A23: =IFERROR(INDEX('Asta Live'!$A$4:$A$403,MATCH(Impostazioni!$B$4&"|"&"C"&"|"&1,'Asta Live'!$J$4:$J$403,0)),"") | B23: =IFERROR(INDEX('Asta Live'!$D$4:$D$403,MATCH(Impostazioni!$B$4&"|"&"C"&"|"&1,'Asta Live'!$J$4:$J$403,0)),"") | C23: =IFERROR(INDEX('Asta Live'!$G$4:$G$403,MATCH(Impostazioni!$B$4&"|"&"C"&"|"&1,'Asta Live'!$J$4:$J$403,0)),"") | E23: =IFERROR(INDEX('Asta Live'!$A$4:$A$403,MATCH(Impostazioni!$B$5&"|"&"C"&"|"&1,'Asta Live'!$J$4:$J$403,0)),"") | F23: =IFERROR(INDEX('Asta Live'!$D$4:$D$403,MATCH(Impostazioni!$B$5&"|"&"C"&"|"&1,'Asta Live'!$J$4:$J$403,0)),"") | G23: =IFERROR(INDEX('Asta Live'!$G$4:$G$403,MATCH(Impostazioni!$B$5&"|"&"C"&"|"&1,'Asta Live'!$J$4:$J$403,0)),"") | I23: =IFERROR(INDEX('Asta Live'!$A$4:$A$403,MATCH(Impostazioni!$B$6&"|"&"C"&"|"&1,'Asta Live'!$J$4:$J$403,0)),"") | J23: =IFERROR(INDEX('Asta Live'!$D$4:$D$403,MATCH(Impostazioni!$B$6&"|"&"C"&"|"&1,'Asta Live'!$J$4:$J$403,0)),"") | K23: =IFERROR(INDEX('Asta Live'!$G$4:$G$403,MATCH(Impostazioni!$B$6&"|"&"C"&"|"&1,'Asta Live'!$J$4:$J$403,0)),"") | M23: =IFERROR(INDEX('Asta Live'!$A$4:$A$403,MATCH(Impostazioni!$B$7&"|"&"C"&"|"&1,'Asta Live'!$J$4:$J$403,0)),"") | N23: =IFERROR(INDEX('Asta Live'!$D$4:$D$403,MATCH(Impostazioni!$B$7&"|"&"C"&"|"&1,'Asta Live'!$J$4:$J$403,0)),"") | O23: =IFERROR(INDEX('Asta Live'!$G$4:$G$403,MATCH(Impostazioni!$B$7&"|"&"C"&"|"&1,'Asta Live'!$J$4:$J$403,0)),"")
A24: =IFERROR(INDEX('Asta Live'!$A$4:$A$403,MATCH(Impostazioni!$B$4&"|"&"C"&"|"&2,'Asta Live'!$J$4:$J$403,0)),"") | B24: =IFERROR(INDEX('Asta Live'!$D$4:$D$403,MATCH(Impostazioni!$B$4&"|"&"C"&"|"&2,'Asta Live'!$J$4:$J$403,0)),"") | C24: =IFERROR(INDEX('Asta Live'!$G$4:$G$403,MATCH(Impostazioni!$B$4&"|"&"C"&"|"&2,'Asta Live'!$J$4:$J$403,0)),"") | E24: =IFERROR(INDEX('Asta Live'!$A$4:$A$403,MATCH(Impostazioni!$B$5&"|"&"C"&"|"&2,'Asta Live'!$J$4:$J$403,0)),"") | F24: =IFERROR(INDEX('Asta Live'!$D$4:$D$403,MATCH(Impostazioni!$B$5&"|"&"C"&"|"&2,'Asta Live'!$J$4:$J$403,0)),"") | G24: =IFERROR(INDEX('Asta Live'!$G$4:$G$403,MATCH(Impostazioni!$B$5&"|"&"C"&"|"&2,'Asta Live'!$J$4:$J$403,0)),"") | I24: =IFERROR(INDEX('Asta Live'!$A$4:$A$403,MATCH(Impostazioni!$B$6&"|"&"C"&"|"&2,'Asta Live'!$J$4:$J$403,0)),"") | J24: =IFERROR(INDEX('Asta Live'!$D$4:$D$403,MATCH(Impostazioni!$B$6&"|"&"C"&"|"&2,'Asta Live'!$J$4:$J$403,0)),"") | K24: =IFERROR(INDEX('Asta Live'!$G$4:$G$403,MATCH(Impostazioni!$B$6&"|"&"C"&"|"&2,'Asta Live'!$J$4:$J$403,0)),"") | M24: =IFERROR(INDEX('Asta Live'!$A$4:$A$403,MATCH(Impostazioni!$B$7&"|"&"C"&"|"&2,'Asta Live'!$J$4:$J$403,0)),"") | N24: =IFERROR(INDEX('Asta Live'!$D$4:$D$403,MATCH(Impostazioni!$B$7&"|"&"C"&"|"&2,'Asta Live'!$J$4:$J$403,0)),"") | O24: =IFERROR(INDEX('Asta Live'!$G$4:$G$403,MATCH(Impostazioni!$B$7&"|"&"C"&"|"&2,'Asta Live'!$J$4:$J$403,0)),"")
A25: =IFERROR(INDEX('Asta Live'!$A$4:$A$403,MATCH(Impostazioni!$B$4&"|"&"C"&"|"&3,'Asta Live'!$J$4:$J$403,0)),"") | B25: =IFERROR(INDEX('Asta Live'!$D$4:$D$403,MATCH(Impostazioni!$B$4&"|"&"C"&"|"&3,'Asta Live'!$J$4:$J$403,0)),"") | C25: =IFERROR(INDEX('Asta Live'!$G$4:$G$403,MATCH(Impostazioni!$B$4&"|"&"C"&"|"&3,'Asta Live'!$J$4:$J$403,0)),"") | E25: =IFERROR(INDEX('Asta Live'!$A$4:$A$403,MATCH(Impostazioni!$B$5&"|"&"C"&"|"&3,'Asta Live'!$J$4:$J$403,0)),"") | F25: =IFERROR(INDEX('Asta Live'!$D$4:$D$403,MATCH(Impostazioni!$B$5&"|"&"C"&"|"&3,'Asta Live'!$J$4:$J$403,0)),"") | G25: =IFERROR(INDEX('Asta Live'!$G$4:$G$403,MATCH(Impostazioni!$B$5&"|"&"C"&"|"&3,'Asta Live'!$J$4:$J$403,0)),"") | I25: =IFERROR(INDEX('Asta Live'!$A$4:$A$403,MATCH(Impostazioni!$B$6&"|"&"C"&"|"&3,'Asta Live'!$J$4:$J$403,0)),"") | J25: =IFERROR(INDEX('Asta Live'!$D$4:$D$403,MATCH(Impostazioni!$B$6&"|"&"C"&"|"&3,'Asta Live'!$J$4:$J$403,0)),"") | K25: =IFERROR(INDEX('Asta Live'!$G$4:$G$403,MATCH(Impostazioni!$B$6&"|"&"C"&"|"&3,'Asta Live'!$J$4:$J$403,0)),"") | M25: =IFERROR(INDEX('Asta Live'!$A$4:$A$403,MATCH(Impostazioni!$B$7&"|"&"C"&"|"&3,'Asta Live'!$J$4:$J$403,0)),"") | N25: =IFERROR(INDEX('Asta Live'!$D$4:$D$403,MATCH(Impostazioni!$B$7&"|"&"C"&"|"&3,'Asta Live'!$J$4:$J$403,0)),"") | O25: =IFERROR(INDEX('Asta Live'!$G$4:$G$403,MATCH(Impostazioni!$B$7&"|"&"C"&"|"&3,'Asta Live'!$J$4:$J$403,0)),"")
